Workbook

Sheet Summary Dashboard
A1: COMPANY A | Master Value Creation Dashboard | PE Cost Transformation — All Data Live from Detail Tabs
A2: All KPIs pull automatically from HC Detail + Non-HC Detail tabs · Blue = Input · Green = Cross-sheet formula
A4: MASTER VALUE CREATION KPIs — live from detail tabs
A5: Total Gross Annual Savings ($) | C5: HC Savings (SG&A) | E5: Non-HC Savings (COGS+SGA+RD) | G5: Total One-Time Costs ($) | I5: Net Annual Savings ($) | K5: Year 1 Realized ($) | M5: Run-Rate Annual ($) | O5: Total FTEs Reduced
A6: =SUM('HC Detail'!$Q$3:$Q$22)+SUM('Non-HC Detail'!$I$3:$I$17) -> 24154000 | C6: =SUM('HC Detail'!$Q$3:$Q$22) -> 3539000 | E6: =SUM('Non-HC Detail'!$I$3:$I$17) -> 20615000 | G6: =SUM('HC Detail'!$P$3:$P$22)+SUM('Non-HC Detail'!$J$3:$J$17) -> 7090115.4 | I6: =SUM('HC Detail'!$Q$3:$Q$22)+SUM('Non-HC Detail'!$I$3:$I$17)-(SUM('HC Detail'!$P$3:$P$22)+SUM('Non-HC Detail'!$J$3:$J$17)) -> 17063885 | K6: =SUM('HC Detail'!$R$3:$R$22)+SUM('Non-HC Detail'!$L$3:$L$17) -> 9505525 | M6: =SUM('HC Detail'!$S$3:$S$22)+SUM('Non-HC Detail'!$M$3:$M$17) -> 24154000 | O6: =SUM('HC Detail'!$G$3:$G$22) -> 20
A8: SAVINGS BY WORKSTREAM — SUMIF from HC Detail col T + Non-HC Detail col D
A9: Workstream | B9: # HC Inits | C9: # Non-HC Inits | D9: HC Savings ($) | E9: Non-HC Savings ($) | F9: Total Gross ($) | G9: One-Time ($) | H9: Net Savings ($) | I9: Yr1 Realized ($)
A10: Manufacturing | B10: =COUNTIF('HC Detail'!$T$3:$T$22,"Manufacturing") -> 0 | C10: =COUNTIF('Non-HC Detail'!$D$3:$D$17,"Manufacturing") -> 2 | D10: =SUMIF('HC Detail'!$T$3:$T$22,"Manufacturing",'HC Detail'!$Q$3:$Q$22) -> 0 | E10: =SUMIF('Non-HC Detail'!$D$3:$D$17,"Manufacturing",'Non-HC Detail'!$I$3:$I$17) -> 6050000 | F10: =D10+E10 -> 6050000 | G10: =SUMIF('HC Detail'!$T$3:$T$22,"Manufacturing",'HC Detail'!$P$3:$P$22)+SUMIF('Non-HC Detail'!$D$3:$D$17,"Manufacturing",'Non-HC Detail'!$J$3:$J$17) -> 2750000 | H10: =F10-G10 -> 3300000 | I10: =SUMIF('HC Detail'!$T$3:$T$22,"Manufacturing",'HC Detail'!$R$3:$R$22)+SUMIF('Non-HC Detail'!$D$3:$D$17,"Manufacturing",'Non-HC Detail'!$L$3:$L$17) -> 1445000
A11: G&A / HC | B11: =COUNTIF('HC Detail'!$T$3:$T$22,"G&A / HC") -> 20 | C11: =COUNTIF('Non-HC Detail'!$D$3:$D$17,"G&A / HC") -> 1 | D11: =SUMIF('HC Detail'!$T$3:$T$22,"G&A / HC",'HC Detail'!$Q$3:$Q$22) -> 3539000 | E11: =SUMIF('Non-HC Detail'!$D$3:$D$17,"G&A / HC",'Non-HC Detail'!$I$3:$I$17) -> 480000 | F11: =D11+E11 -> 4019000 | G11: =SUMIF('HC Detail'!$T$3:$T$22,"G&A / HC",'HC Detail'!$P$3:$P$22)+SUMIF('Non-HC Detail'!$D$3:$D$17,"G&A / HC",'Non-HC Detail'!$J$3:$J$17) -> 1095115.4 | H11: =F11-G11 -> 2923884.6 | I11: =SUMIF('HC Detail'!$T$3:$T$22,"G&A / HC",'HC Detail'!$R$3:$R$22)+SUMIF('Non-HC Detail'!$D$3:$D$17,"G&A / HC",'Non-HC Detail'!$L$3:$L$17) -> 1752525
A12: Procurement | B12: =COUNTIF('HC Detail'!$T$3:$T$22,"Procurement") -> 0 | C12: =COUNTIF('Non-HC Detail'!$D$3:$D$17,"Procurement") -> 3 | D12: =SUMIF('HC Detail'!$T$3:$T$22,"Procurement",'HC Detail'!$Q$3:$Q$22) -> 0 | E12: =SUMIF('Non-HC Detail'!$D$3:$D$17,"Procurement",'Non-HC Detail'!$I$3:$I$17) -> 5175000 | F12: =D12+E12 -> 5175000 | G12: =SUMIF('HC Detail'!$T$3:$T$22,"Procurement",'HC Detail'!$P$3:$P$22)+SUMIF('Non-HC Detail'!$D$3:$D$17,"Procurement",'Non-HC Detail'!$J$3:$J$17) -> 280000 | H12: =F12-G12 -> 4895000 | I12: =SUMIF('HC Detail'!$T$3:$T$22,"Procurement",'HC Detail'!$R$3:$R$22)+SUMIF('Non-HC Detail'!$D$3:$D$17,"Procurement",'Non-HC Detail'!$L$3:$L$17) -> 2325000
A13: Marketing | B13: =COUNTIF('HC Detail'!$T$3:$T$22,"Marketing") -> 0 | C13: =COUNTIF('Non-HC Detail'!$D$3:$D$17,"Marketing") -> 2 | D13: =SUMIF('HC Detail'!$T$3:$T$22,"Marketing",'HC Detail'!$Q$3:$Q$22) -> 0 | E13: =SUMIF('Non-HC Detail'!$D$3:$D$17,"Marketing",'Non-HC Detail'!$I$3:$I$17) -> 1330000 | F13: =D13+E13 -> 1330000 | G13: =SUMIF('HC Detail'!$T$3:$T$22,"Marketing",'HC Detail'!$P$3:$P$22)+SUMIF('Non-HC Detail'!$D$3:$D$17,"Marketing",'Non-HC Detail'!$J$3:$J$17) -> 195000 | H13: =F13-G13 -> 1135000 | I13: =SUMIF('HC Detail'!$T$3:$T$22,"Marketing",'HC Detail'!$R$3:$R$22)+SUMIF('Non-HC Detail'!$D$3:$D$17,"Marketing",'Non-HC Detail'!$L$3:$L$17) -> 627000
A14: Technology | B14: =COUNTIF('HC Detail'!$T$3:$T$22,"Technology") -> 0 | C14: =COUNTIF('Non-HC Detail'!$D$3:$D$17,"Technology") -> 3 | D14: =SUMIF('HC Detail'!$T$3:$T$22,"Technology",'HC Detail'!$Q$3:$Q$22) -> 0 | E14: =SUMIF('Non-HC Detail'!$D$3:$D$17,"Technology",'Non-HC Detail'!$I$3:$I$17) -> 4620000 | F14: =D14+E14 -> 4620000 | G14: =SUMIF('HC Detail'!$T$3:$T$22,"Technology",'HC Detail'!$P$3:$P$22)+SUMIF('Non-HC Detail'!$D$3:$D$17,"Technology",'Non-HC Detail'!$J$3:$J$17) -> 2430000 | H14: =F14-G14 -> 2190000 | I14: =SUMIF('HC Detail'!$T$3:$T$22,"Technology",'HC Detail'!$R$3:$R$22)+SUMIF('Non-HC Detail'!$D$3:$D$17,"Technology",'Non-HC Detail'!$L$3:$L$17) -> 1470000
A15: Distribution | B15: =COUNTIF('HC Detail'!$T$3:$T$22,"Distribution") -> 0 | C15: =COUNTIF('Non-HC Detail'!$D$3:$D$17,"Distribution") -> 2 | D15: =SUMIF('HC Detail'!$T$3:$T$22,"Distribution",'HC Detail'!$Q$3:$Q$22) -> 0 | E15: =SUMIF('Non-HC Detail'!$D$3:$D$17,"Distribution",'Non-HC Detail'!$I$3:$I$17) -> 1100000 | F15: =D15+E15 -> 1100000 | G15: =SUMIF('HC Detail'!$T$3:$T$22,"Distribution",'HC Detail'!$P$3:$P$22)+SUMIF('Non-HC Detail'!$D$3:$D$17,"Distribution",'Non-HC Detail'!$J$3:$J$17) -> 160000 | H15: =F15-G15 -> 940000 | I15: =SUMIF('HC Detail'!$T$3:$T$22,"Distribution",'HC Detail'!$R$3:$R$22)+SUMIF('Non-HC Detail'!$D$3:$D$17,"Distribution",'Non-HC Detail'!$L$3:$L$17) -> 406000
A16: Public-to-Private | B16: =COUNTIF('HC Detail'!$T$3:$T$22,"Public-to-Private") -> 0 | C16: =COUNTIF('Non-HC Detail'!$D$3:$D$17,"Public-to-Private") -> 2 | D16: =SUMIF('HC Detail'!$T$3:$T$22,"Public-to-Private",'HC Detail'!$Q$3:$Q$22) -> 0 | E16: =SUMIF('Non-HC Detail'!$D$3:$D$17,"Public-to-Private",'Non-HC Detail'!$I$3:$I$17) -> 1860000 | F16: =D16+E16 -> 1860000 | G16: =SUMIF('HC Detail'!$T$3:$T$22,"Public-to-Private",'HC Detail'!$P$3:$P$22)+SUMIF('Non-HC Detail'!$D$3:$D$17,"Public-to-Private",'Non-HC Detail'!$J$3:$J$17) -> 180000 | H16: =F16-G16 -> 1680000 | I16: =SUMIF('HC Detail'!$T$3:$T$22,"Public-to-Private",'HC Detail'!$R$3:$R$22)+SUMIF('Non-HC Detail'!$D$3:$D$17,"Public-to-Private",'Non-HC Detail'!$L$3:$L$17) -> 1480000
A17: TOTAL | D17: =SUM(D10:D16) -> 3539000 | E17: =SUM(E10:E16) -> 20615000 | F17: =SUM(F10:F16) -> 24154000 | G17: =SUM(G10:G16) -> 7090115.4 | H17: =SUM(H10:H16) -> 17063885 | I17: =SUM(I10:I16) -> 9505525
A19: SAVINGS BY SEGMENT — SUMPRODUCT from HC Detail + Non-HC Detail
A20: Segment | B20: HC Savings ($) | C20: Non-HC Savings ($) | D20: Total Gross ($) | E20: One-Time ($) | F20: Net ($) | G20: Yr1 ($) | H20: Run-Rate ($) | I20: % of Total
A21: Dx — Diagnostics | B21: =SUMPRODUCT(('HC Detail'!$X$3:$X$22="Dx")*'HC Detail'!$Q$3:$Q$22) -> 1514312.5 | C21: =SUMPRODUCT(('Non-HC Detail'!$C$3:$C$17="Dx")*'Non-HC Detail'!$I$3:$I$17) -> 11100000 | D21: =B21+C21 -> 12614312 | E21: =SUMPRODUCT(('HC Detail'!$X$3:$X$22="Dx")*'HC Detail'!$P$3:$P$22)+SUMPRODUCT(('Non-HC Detail'!$C$3:$C$17="Dx")*'Non-HC Detail'!$J$3:$J$17) -> 2911846.2 | F21: =D21-E21 -> 9702466.3 | G21: =SUMPRODUCT(('HC Detail'!$X$3:$X$22="Dx")*'HC Detail'!$R$3:$R$22)+SUMPRODUCT(('Non-HC Detail'!$C$3:$C$17="Dx")*'Non-HC Detail'!$L$3:$L$17) -> 4983800 | H21: =SUMPRODUCT(('HC Detail'!$X$3:$X$22="Dx")*'HC Detail'!$S$3:$S$22)+SUMPRODUCT(('Non-HC Detail'!$C$3:$C$17="Dx")*'Non-HC Detail'!$M$3:$M$17) -> 12614312 | I21: =IFERROR(D21/D24,"-") -> 0.52224528
A22: BH — Breast Health | B22: =SUMPRODUCT(('HC Detail'!$X$3:$X$22="BH")*'HC Detail'!$Q$3:$Q$22) -> 1169687.5 | C22: =SUMPRODUCT(('Non-HC Detail'!$C$3:$C$17="BH")*'Non-HC Detail'!$I$3:$I$17) -> 6170000 | D22: =B22+C22 -> 7339687.5 | E22: =SUMPRODUCT(('HC Detail'!$X$3:$X$22="BH")*'HC Detail'!$P$3:$P$22)+SUMPRODUCT(('Non-HC Detail'!$C$3:$C$17="BH")*'Non-HC Detail'!$J$3:$J$17) -> 3852423.1 | F22: =D22-E22 -> 3487264.4 | G22: =SUMPRODUCT(('HC Detail'!$X$3:$X$22="BH")*'HC Detail'!$R$3:$R$22)+SUMPRODUCT(('Non-HC Detail'!$C$3:$C$17="BH")*'Non-HC Detail'!$L$3:$L$17) -> 2141281.2 | H22: =SUMPRODUCT(('HC Detail'!$X$3:$X$22="BH")*'HC Detail'!$S$3:$S$22)+SUMPRODUCT(('Non-HC Detail'!$C$3:$C$17="BH")*'Non-HC Detail'!$M$3:$M$17) -> 7339687.5 | I22: =IFERROR(D22/D24,"-") -> 0.30387048
A23: GY — GYN Surgical | B23: =SUMPRODUCT(('HC Detail'!$X$3:$X$22="GY")*'HC Detail'!$Q$3:$Q$22) -> 855000 | C23: =SUMPRODUCT(('Non-HC Detail'!$C$3:$C$17="GY")*'Non-HC Detail'!$I$3:$I$17) -> 3345000 | D23: =B23+C23 -> 4200000 | E23: =SUMPRODUCT(('HC Detail'!$X$3:$X$22="GY")*'HC Detail'!$P$3:$P$22)+SUMPRODUCT(('Non-HC Detail'!$C$3:$C$17="GY")*'Non-HC Detail'!$J$3:$J$17) -> 325846.15 | F23: =D23-E23 -> 3874153.8 | G23: =SUMPRODUCT(('HC Detail'!$X$3:$X$22="GY")*'HC Detail'!$R$3:$R$22)+SUMPRODUCT(('Non-HC Detail'!$C$3:$C$17="GY")*'Non-HC Detail'!$L$3:$L$17) -> 2380443.8 | H23: =SUMPRODUCT(('HC Detail'!$X$3:$X$22="GY")*'HC Detail'!$S$3:$S$22)+SUMPRODUCT(('Non-HC Detail'!$C$3:$C$17="GY")*'Non-HC Detail'!$M$3:$M$17) -> 4200000 | I23: =IFERROR(D23/D24,"-") -> 0.17388424
A24: TOTAL | B24: =SUM(B21:B23) -> 3539000 | C24: =SUM(C21:C23) -> 20615000 | D24: =SUM(D21:D23) -> 24154000 | E24: =SUM(E21:E23) -> 7090115.4 | F24: =SUM(F21:F23) -> 17063885 | G24: =SUM(G21:G23) -> 9505525 | H24: =SUM(H21:H23) -> 24154000 | I24: 100.0%
A26: 3-YEAR SAVINGS RAMP — from detail tabs
A27: P&L Line | B27: Year 1 ($) | C27: Year 2 ($) | D27: Year 3 Run-Rate ($) | E27: Cum. Yr1 ($) | F27: Cum. Yr2 ($) | G27: Cum. Yr3 ($) | H27: One-Time Costs ($) | I27: Payback (Yrs)
A28: COGS | B28: =SUMPRODUCT(('HC Detail'!$U$3:$U$22="COGS")*'HC Detail'!$R$3:$R$22)+SUMPRODUCT(('Non-HC Detail'!$V$3:$V$17="COGS")*'Non-HC Detail'!$L$3:$L$17) -> 4176000 | C28: =D28*0.9 -> 11092500 | D28: =SUMPRODUCT(('HC Detail'!$U$3:$U$22="COGS")*'HC Detail'!$S$3:$S$22)+SUMPRODUCT(('Non-HC Detail'!$V$3:$V$17="COGS")*'Non-HC Detail'!$M$3:$M$17) -> 12325000 | E28: =B28 -> 4176000 | F28: =E28+C28 -> 15268500 | G28: =F28+D28 -> 27593500 | H28: =SUMPRODUCT(('HC Detail'!$U$3:$U$22="COGS")*'HC Detail'!$P$3:$P$22)+SUMPRODUCT(('Non-HC Detail'!$V$3:$V$17="COGS")*'Non-HC Detail'!$J$3:$J$17) -> 3190000 | I28: =IFERROR(H28/D28,"-") -> 0.25882353
A29: SGA | B29: =SUMPRODUCT(('HC Detail'!$U$3:$U$22="SGA")*'HC Detail'!$R$3:$R$22)+SUMPRODUCT(('Non-HC Detail'!$V$3:$V$17="SGA")*'Non-HC Detail'!$L$3:$L$17) -> 4209525 | C29: =D29*0.9 -> 8126100 | D29: =SUMPRODUCT(('HC Detail'!$U$3:$U$22="SGA")*'HC Detail'!$S$3:$S$22)+SUMPRODUCT(('Non-HC Detail'!$V$3:$V$17="SGA")*'Non-HC Detail'!$M$3:$M$17) -> 9029000 | E29: =B29 -> 4209525 | F29: =E29+C29 -> 12335625 | G29: =F29+D29 -> 21364625 | H29: =SUMPRODUCT(('HC Detail'!$U$3:$U$22="SGA")*'HC Detail'!$P$3:$P$22)+SUMPRODUCT(('Non-HC Detail'!$V$3:$V$17="SGA")*'Non-HC Detail'!$J$3:$J$17) -> 3700115.4 | I29: =IFERROR(H29/D29,"-") -> 0.40980345
A30: RD | B30: =SUMPRODUCT(('HC Detail'!$U$3:$U$22="RD")*'HC Detail'!$R$3:$R$22)+SUMPRODUCT(('Non-HC Detail'!$V$3:$V$17="RD")*'Non-HC Detail'!$L$3:$L$17) -> 1120000 | C30: =D30*0.9 -> 2520000 | D30: =SUMPRODUCT(('HC Detail'!$U$3:$U$22="RD")*'HC Detail'!$S$3:$S$22)+SUMPRODUCT(('Non-HC Detail'!$V$3:$V$17="RD")*'Non-HC Detail'!$M$3:$M$17) -> 2800000 | E30: =B30 -> 1120000 | F30: =E30+C30 -> 3640000 | G30: =F30+D30 -> 6440000 | H30: =SUMPRODUCT(('HC Detail'!$U$3:$U$22="RD")*'HC Detail'!$P$3:$P$22)+SUMPRODUCT(('Non-HC Detail'!$V$3:$V$17="RD")*'Non-HC Detail'!$J$3:$J$17) -> 200000 | I30: =IFERROR(H30/D30,"-") -> 0.071428571
A31: TOTAL | B31: =SUM(B28:B30) -> 9505525 | C31: =SUM(C28:C30) -> 21738600 | D31: =SUM(D28:D30) -> 24154000 | E31: =SUM(E28:E30) -> 9505525 | F31: =SUM(F28:F30) -> 31244125 | G31: =SUM(G28:G30) -> 55398125 | H31: =SUM(H28:H30) -> 7090115.4

Sheet Manufacturing Summary
A1: COMPANY A | Manufacturing | Value Creation Summary — All data from detail tabs
A3: KEY METRICS — MANUFACTURING (formulas pull from HC Detail + Non-HC Detail tabs)
A4: # Initiatives | C4: Gross Annual Savings ($) | E4: One-Time Costs ($) | G4: Net Annual Savings ($) | I4: Year 1 Realized ($) | K4: Run-Rate (Yr3) ($) | M4: Upside Scenario ($)
A5: =COUNTIF('HC Detail'!$T$3:$T$22,"Manufacturing")+COUNTIF('Non-HC Detail'!$D$3:$D$17,"Manufacturing") -> 2 | C5: =SUMIF('Non-HC Detail'!$D$3:$D$17,"Manufacturing",'Non-HC Detail'!$I$3:$I$17) -> 6050000 | E5: =SUMIF('Non-HC Detail'!$D$3:$D$17,"Manufacturing",'Non-HC Detail'!$J$3:$J$17) -> 2750000 | G5: =SUMIF('Non-HC Detail'!$D$3:$D$17,"Manufacturing",'Non-HC Detail'!$I$3:$I$17)-(SUMIF('Non-HC Detail'!$D$3:$D$17,"Manufacturing",'Non-HC Detail'!$J$3:$J$17)) -> 3300000 | I5: =SUMIF('Non-HC Detail'!$D$3:$D$17,"Manufacturing",'Non-HC Detail'!$L$3:$L$17) -> 1445000 | K5: =SUMIF('Non-HC Detail'!$D$3:$D$17,"Manufacturing",'Non-HC Detail'!$I$3:$I$17) -> 6050000 | M5: =SUMIF('Non-HC Detail'!$D$3:$D$17,"Manufacturing",'Non-HC Detail'!$I$3:$I$17)*1.15 -> 6957500
A7: INITIATIVE DETAIL — live from Non-HC Detail where Topic = 'Manufacturing'
A8: Initiative ID | B8: Initiative Name | C8: Segment | D8: Owner | E8: P&L Line | F8: Status | G8: Gross Annual Savings ($) | H8: One-Time Cost ($) | I8: Net Annual Savings ($) | J8: Yr1 Realized ($) | K8: Run-Rate ($) | L8: Upside Scenario ($) | M8: Baseline Scenario ($) | N8: Notes
A9: I-011 | B9: San Diego Mfg Plant Closure | C9: Dx | D9: COO | E9: COGS | F9: Active | G9: 4200000 | H9: 1800000 | I9: 2400000 | J9: 1260000 | K9: 4200000 | L9: 4830000 | M9: 3570000
A10: I-012 | B10: Marlborough Facility Consolidation | C10: BH | D10: COO | E10: COGS | F10: Pipeline | G10: 1850000 | H10: 950000 | I10: 900000 | J10: 185000 | K10: 1850000 | L10: 2127500 | M10: 1572500
A11: TOTALS — from Initiative Log | G11: =SUM(G9:G10) -> 6050000 | H11: =SUM(H9:H10) -> 2750000 | I11: =SUM(I9:I10) -> 3300000 | J11: =SUM(J9:J10) -> 1445000 | K11: =SUM(K9:K10) -> 6050000 | L11: =SUM(L9:L10) -> 6957500 | M11: =SUM(M9:M10) -> 5142500
A13: SCENARIO ANALYSIS — MANUFACTURING (Upside / Base / Downside)
A14: Scenario | B14: Description | C14: Gross Savings ($) | D14: vs. Plan ($) | E14: vs. Plan (%) | F14: One-Time ($) | G14: Net Savings ($) | H14: Key Assumptions
A15: Upside | B15: Full capture; all Active, above plan | C15: 6957499 | D15: =C15-6050000 -> 907499 | E15: =IFERROR(C15/6050000-1,"-") -> 0.14999983 | F15: 2475000 | G15: =C15-F15 -> 4482499 | H15: Full execution; procurement/vendor beats target; no timeline slippage
A16: Base Plan | B16: Current plan; Active + Pipeline mix | C16: 6050000 | D16: =C16-6050000 -> 0 | E16: =IFERROR(C16/6050000-1,"-") -> 0 | F16: 2750000 | G16: =C16-F16 -> 3300000 | H16: Current initiative slate; on-schedule execution; no scope changes
A17: Downside | B17: Partial capture; delays, scope cuts | C17: 4537500 | D17: =C17-6050000 -> -1512500 | E17: =IFERROR(C17/6050000-1,"-") -> -0.25 | F17: 3025000 | G17: =C17-F17 -> 1512500 | H17: 3-4 initiatives delayed; savings reduced 25%; facility timeline slip

Sheet G&A & HC Summary
A1: COMPANY A | G&A / HC | Value Creation Summary — All data from detail tabs
A3: KEY METRICS — G&A / HC (formulas pull from HC Detail + Non-HC Detail tabs)
A4: # Initiatives | C4: Gross Annual Savings ($) | E4: One-Time Costs ($) | G4: Net Annual Savings ($) | I4: Year 1 Realized ($) | K4: Run-Rate (Yr3) ($) | M4: Upside Scenario ($)
A5: =COUNTIF('HC Detail'!$T$3:$T$22,"G&A / HC")+COUNTIF('Non-HC Detail'!$D$3:$D$17,"G&A / HC") -> 21 | C5: =SUMIF('HC Detail'!$T$3:$T$22,"G&A / HC",'HC Detail'!$Q$3:$Q$22)+SUMIF('Non-HC Detail'!$D$3:$D$17,"G&A / HC",'Non-HC Detail'!$I$3:$I$17) -> 4019000 | E5: =SUMIF('HC Detail'!$T$3:$T$22,"G&A / HC",'HC Detail'!$P$3:$P$22)+SUMIF('Non-HC Detail'!$D$3:$D$17,"G&A / HC",'Non-HC Detail'!$J$3:$J$17) -> 1095115.4 | G5: =SUMIF('HC Detail'!$T$3:$T$22,"G&A / HC",'HC Detail'!$Q$3:$Q$22)+SUMIF('Non-HC Detail'!$D$3:$D$17,"G&A / HC",'Non-HC Detail'!$I$3:$I$17)-(SUMIF('HC Detail'!$T$3:$T$22,"G&A / HC",'HC Detail'!$P$3:$P$22)+SUMIF('Non-HC Detail'!$D$3:$D$17,"G&A / HC",'Non-HC Detail'!$J$3:$J$17)) -> 2923884.6 | I5: =SUMIF('HC Detail'!$T$3:$T$22,"G&A / HC",'HC Detail'!$R$3:$R$22)+SUMIF('Non-HC Detail'!$D$3:$D$17,"G&A / HC",'Non-HC Detail'!$L$3:$L$17) -> 1752525 | K5: =SUMIF('HC Detail'!$T$3:$T$22,"G&A / HC",'HC Detail'!$Q$3:$Q$22)+SUMIF('Non-HC Detail'!$D$3:$D$17,"G&A / HC",'Non-HC Detail'!$I$3:$I$17) -> 4019000 | M5: =SUMIF('HC Detail'!$T$3:$T$22,"G&A / HC",'HC Detail'!$Q$3:$Q$22)+SUMIF('Non-HC Detail'!$D$3:$D$17,"G&A / HC",'Non-HC Detail'!$I$3:$I$17)*1.15 -> 4091000
A7: INITIATIVE DETAIL — live from HC Detail + Non-HC Detail where Topic = 'G&A / HC'
A8: Initiative ID | B8: Initiative Name | C8: Segment | D8: Owner | E8: P&L Line | F8: Status | G8: Gross Annual Savings ($) | H8: One-Time Cost ($) | I8: Net Annual Savings ($) | J8: Yr1 Realized ($) | K8: Run-Rate ($) | L8: Upside Scenario ($) | M8: Baseline Scenario ($) | N8: Notes
A9: I-001 | B9: VP Molecular Dx Elimination | C9: Dx | D9: CFO | E9: SGA | F9: Active | G9: 320000 | H9: 45000 | I9: 275000 | J9: 160000 | K9: 320000 | L9: 368000 | M9: 272000
A10: I-002 | B10: Director Clinical Affairs Reduction | C10: Dx | D10: CHRO | E10: SGA | F10: Active | G10: 385000 | H10: 65000 | I10: 320000 | J10: 154000 | K10: 385000 | L10: 442749 | M10: 327250
A11: I-003 | B11: Regional Sales Manager Reduction (3) | C11: BH | D11: CSO | E11: SGA | F11: Active | G11: 480000 | H11: 60000 | I11: 420000 | J11: 240000 | K11: 480000 | L11: 552000 | M11: 408000
A12: I-004 | B12: Field Service Engineer Optimization (2) | C12: BH | D12: COO | E12: SGA | F12: Pipeline | G12: 275000 | H12: 35000 | I12: 240000 | J12: 55000 | K12: 275000 | L12: 316250 | M12: 233750
A13: I-005 | B13: GYN Surgical Marketing Manager | C13: GY | D13: CMO | E13: SGA | F13: Active | G13: 185000 | H13: 25000 | I13: 160000 | J13: 92500 | K13: 185000 | L13: 212749 | M13: 157250
A14: I-006 | B14: Inside Sales Rep Reduction (4) | C14: GY | D14: CSO | E14: SGA | F14: Pipeline | G14: 340000 | H14: 50000 | I14: 290000 | J14: 68000 | K14: 340000 | L14: 390999 | M14: 289000
A15: I-007 | B15: Regulatory Affairs Reduction (2) | C15: Dx | D15: CLO | E15: SGA | F15: Active | G15: 260000 | H15: 30000 | I15: 230000 | J15: 104000 | K15: 260000 | L15: 299000 | M15: 221000
A16: I-008 | B16: Director Quality Systems Consol | C16: BH | D16: COO | E16: SGA | F16: Active | G16: 230000 | H16: 35000 | I16: 195000 | J16: 115000 | K16: 230000 | L16: 264500 | M16: 195500
A17: I-009 | B17: Finance Analyst Reduction (2) | C17: GY | D17: CFO | E17: SGA | F17: Complete | G17: 180000 | H17: 20000 | I17: 160000 | J17: 180000 | K17: 180000 | L17: 206999 | M17: 153000
A18: I-010 | B18: IT Infrastructure Staff Reduction (2) | C18: Dx | D18: CIO | E18: SGA | F18: Pipeline | G18: 210000 | H18: 40000 | I18: 170000 | J18: 42000 | K18: 210000 | L18: 241499 | M18: 178500
A19: I-025 | B19: Travel & Expense Policy Tightening | C19: BH | D19: CFO | E19: SGA | F19: Active | G19: 480000 | H19: 25000 | I19: 455000 | J19: 240000 | K19: 480000 | L19: 552000 | M19: 408000
A20: TOTALS — from Initiative Log | G20: =SUM(G9:G19) -> 3345000 | H20: =SUM(H9:H19) -> 430000 | I20: =SUM(I9:I19) -> 2915000 | J20: =SUM(J9:J19) -> 1450500 | K20: =SUM(K9:K19) -> 3345000 | L20: =SUM(L9:L19) -> 3846745 | M20: =SUM(M9:M19) -> 2843250
A22: SCENARIO ANALYSIS — G&A / HC (Upside / Base / Downside)
A23: Scenario | B23: Description | C23: Gross Savings ($) | D23: vs. Plan ($) | E23: vs. Plan (%) | F23: One-Time ($) | G23: Net Savings ($) | H23: Key Assumptions
A24: Upside | B24: Full capture; all Active, above plan | C24: 3846749 | D24: =C24-3345000 -> 501749 | E24: =IFERROR(C24/3345000-1,"-") -> 0.1499997 | F24: 387000 | G24: =C24-F24 -> 3459749 | H24: Full execution; procurement/vendor beats target; no timeline slippage
A25: Base Plan | B25: Current plan; Active + Pipeline mix | C25: 3345000 | D25: =C25-3345000 -> 0 | E25: =IFERROR(C25/3345000-1,"-") -> 0 | F25: 430000 | G25: =C25-F25 -> 2915000 | H25: Current initiative slate; on-schedule execution; no scope changes
A26: Downside | B26: Partial capture; delays, scope cuts | C26: 2508750 | D26: =C26-3345000 -> -836250 | E26: =IFERROR(C26/3345000-1,"-") -> -0.25 | F26: 473000 | G26: =C26-F26 -> 2035750 | H26: 3-4 initiatives delayed; savings reduced 25%; facility timeline slip

Sheet Procurement Summary
A1: COMPANY A | Procurement | Value Creation Summary — All data from detail tabs
A3: KEY METRICS — PROCUREMENT (formulas pull from HC Detail + Non-HC Detail tabs)
A4: # Initiatives | C4: Gross Annual Savings ($) | E4: One-Time Costs ($) | G4: Net Annual Savings ($) | I4: Year 1 Realized ($) | K4: Run-Rate (Yr3) ($) | M4: Upside Scenario ($)
A5: =COUNTIF('HC Detail'!$T$3:$T$22,"Procurement")+COUNTIF('Non-HC Detail'!$D$3:$D$17,"Procurement") -> 3 | C5: =SUMIF('Non-HC Detail'!$D$3:$D$17,"Procurement",'Non-HC Detail'!$I$3:$I$17) -> 5175000 | E5: =SUMIF('Non-HC Detail'!$D$3:$D$17,"Procurement",'Non-HC Detail'!$J$3:$J$17) -> 280000 | G5: =SUMIF('Non-HC Detail'!$D$3:$D$17,"Procurement",'Non-HC Detail'!$I$3:$I$17)-(SUMIF('Non-HC Detail'!$D$3:$D$17,"Procurement",'Non-HC Detail'!$J$3:$J$17)) -> 4895000 | I5: =SUMIF('Non-HC Detail'!$D$3:$D$17,"Procurement",'Non-HC Detail'!$L$3:$L$17) -> 2325000 | K5: =SUMIF('Non-HC Detail'!$D$3:$D$17,"Procurement",'Non-HC Detail'!$I$3:$I$17) -> 5175000 | M5: =SUMIF('Non-HC Detail'!$D$3:$D$17,"Procurement",'Non-HC Detail'!$I$3:$I$17)*1.15 -> 5951250
A7: INITIATIVE DETAIL — live from Non-HC Detail where Topic = 'Procurement'
A8: Initiative ID | B8: Initiative Name | C8: Segment | D8: Owner | E8: P&L Line | F8: Status | G8: Gross Annual Savings ($) | H8: One-Time Cost ($) | I8: Net Annual Savings ($) | J8: Yr1 Realized ($) | K8: Run-Rate ($) | L8: Upside Scenario ($) | M8: Baseline Scenario ($) | N8: Notes
A9: I-013 | B9: Reagent Supplier Renegotiation | C9: Dx | D9: CPO | E9: COGS | F9: Active | G9: 3100000 | H9: 150000 | I9: 2950000 | J9: 1550000 | K9: 3100000 | L9: 3564999 | M9: 2635000
A10: I-014 | B10: Capital Equipment Vendor Consolidation | C10: BH | D10: CPO | E10: COGS | F10: Active | G10: 1200000 | H10: 80000 | I10: 1120000 | J10: 600000 | K10: 1200000 | L10: 1380000 | M10: 1020000
A11: I-015 | B11: Surgical Consumables GPO Enrollment | C11: GY | D11: CPO | E11: COGS | F11: Pipeline | G11: 875000 | H11: 50000 | I11: 825000 | J11: 175000 | K11: 875000 | L11: 1006249 | M11: 743750
A12: TOTALS — from Initiative Log | G12: =SUM(G9:G11) -> 5175000 | H12: =SUM(H9:H11) -> 280000 | I12: =SUM(I9:I11) -> 4895000 | J12: =SUM(J9:J11) -> 2325000 | K12: =SUM(K9:K11) -> 5175000 | L12: =SUM(L9:L11) -> 5951248 | M12: =SUM(M9:M11) -> 4398750
A14: SCENARIO ANALYSIS — PROCUREMENT (Upside / Base / Downside)
A15: Scenario | B15: Description | C15: Gross Savings ($) | D15: vs. Plan ($) | E15: vs. Plan (%) | F15: One-Time ($) | G15: Net Savings ($) | H15: Key Assumptions
A16: Upside | B16: Full capture; all Active, above plan | C16: 5951250 | D16: =C16-5175000 -> 776250 | E16: =IFERROR(C16/5175000-1,"-") -> 0.15 | F16: 252000 | G16: =C16-F16 -> 5699250 | H16: Full execution; procurement/vendor beats target; no timeline slippage
A17: Base Plan | B17: Current plan; Active + Pipeline mix | C17: 5175000 | D17: =C17-5175000 -> 0 | E17: =IFERROR(C17/5175000-1,"-") -> 0 | F17: 280000 | G17: =C17-F17 -> 4895000 | H17: Current initiative slate; on-schedule execution; no scope changes
A18: Downside | B18: Partial capture; delays, scope cuts | C18: 3881250 | D18: =C18-5175000 -> -1293750 | E18: =IFERROR(C18/5175000-1,"-") -> -0.25 | F18: 308000 | G18: =C18-F18 -> 3573250 | H18: 3-4 initiatives delayed; savings reduced 25%; facility timeline slip

Sheet Marketing Summary
A1: COMPANY A | Marketing | Value Creation Summary — All data from detail tabs
A3: KEY METRICS — MARKETING (formulas pull from HC Detail + Non-HC Detail tabs)
A4: # Initiatives | C4: Gross Annual Savings ($) | E4: One-Time Costs ($) | G4: Net Annual Savings ($) | I4: Year 1 Realized ($) | K4: Run-Rate (Yr3) ($) | M4: Upside Scenario ($)
A5: =COUNTIF('HC Detail'!$T$3:$T$22,"Marketing")+COUNTIF('Non-HC Detail'!$D$3:$D$17,"Marketing") -> 2 | C5: =SUMIF('Non-HC Detail'!$D$3:$D$17,"Marketing",'Non-HC Detail'!$I$3:$I$17) -> 1330000 | E5: =SUMIF('Non-HC Detail'!$D$3:$D$17,"Marketing",'Non-HC Detail'!$J$3:$J$17) -> 195000 | G5: =SUMIF('Non-HC Detail'!$D$3:$D$17,"Marketing",'Non-HC Detail'!$I$3:$I$17)-(SUMIF('Non-HC Detail'!$D$3:$D$17,"Marketing",'Non-HC Detail'!$J$3:$J$17)) -> 1135000 | I5: =SUMIF('Non-HC Detail'!$D$3:$D$17,"Marketing",'Non-HC Detail'!$L$3:$L$17) -> 627000 | K5: =SUMIF('Non-HC Detail'!$D$3:$D$17,"Marketing",'Non-HC Detail'!$I$3:$I$17) -> 1330000 | M5: =SUMIF('Non-HC Detail'!$D$3:$D$17,"Marketing",'Non-HC Detail'!$I$3:$I$17)*1.15 -> 1529500
A7: INITIATIVE DETAIL — live from Non-HC Detail where Topic = 'Marketing'
A8: Initiative ID | B8: Initiative Name | C8: Segment | D8: Owner | E8: P&L Line | F8: Status | G8: Gross Annual Savings ($) | H8: One-Time Cost ($) | I8: Net Annual Savings ($) | J8: Yr1 Realized ($) | K8: Run-Rate ($) | L8: Upside Scenario ($) | M8: Baseline Scenario ($) | N8: Notes
A9: I-018 | B9: Marketing Agency Rationalization | C9: GY | D9: CMO | E9: SGA | F9: Active | G9: 950000 | H9: 75000 | I9: 875000 | J9: 475000 | K9: 950000 | L9: 1092500 | M9: 807500
A10: I-019 | B10: Digital Marketing Platform Consolidation | C10: Dx | D10: CMO | E10: SGA | F10: Active | G10: 380000 | H10: 120000 | I10: 260000 | J10: 152000 | K10: 380000 | L10: 436999 | M10: 323000
A11: TOTALS — from Initiative Log | G11: =SUM(G9:G10) -> 1330000 | H11: =SUM(H9:H10) -> 195000 | I11: =SUM(I9:I10) -> 1135000 | J11: =SUM(J9:J10) -> 627000 | K11: =SUM(K9:K10) -> 1330000 | L11: =SUM(L9:L10) -> 1529499 | M11: =SUM(M9:M10) -> 1130500
A13: SCENARIO ANALYSIS — MARKETING (Upside / Base / Downside)
A14: Scenario | B14: Description | C14: Gross Savings ($) | D14: vs. Plan ($) | E14: vs. Plan (%) | F14: One-Time ($) | G14: Net Savings ($) | H14: Key Assumptions
A15: Upside | B15: Full capture; all Active, above plan | C15: 1529499 | D15: =C15-1330000 -> 199499 | E15: =IFERROR(C15/1330000-1,"-") -> 0.14999925 | F15: 175500 | G15: =C15-F15 -> 1353999 | H15: Full execution; procurement/vendor beats target; no timeline slippage
A16: Base Plan | B16: Current plan; Active + Pipeline mix | C16: 1330000 | D16: =C16-1330000 -> 0 | E16: =IFERROR(C16/1330000-1,"-") -> 0 | F16: 195000 | G16: =C16-F16 -> 1135000 | H16: Current initiative slate; on-schedule execution; no scope changes
A17: Downside | B17: Partial capture; delays, scope cuts | C17: 997500 | D17: =C17-1330000 -> -332500 | E17: =IFERROR(C17/1330000-1,"-") -> -0.25 | F17: 214500 | G17: =C17-F17 -> 783000 | H17: 3-4 initiatives delayed; savings reduced 25%; facility timeline slip

Sheet Technology Summary
A1: COMPANY A | Technology | Value Creation Summary — All data from detail tabs
A3: KEY METRICS — TECHNOLOGY (formulas pull from HC Detail + Non-HC Detail tabs)
A4: # Initiatives | C4: Gross Annual Savings ($) | E4: One-Time Costs ($) | G4: Net Annual Savings ($) | I4: Year 1 Realized ($) | K4: Run-Rate (Yr3) ($) | M4: Upside Scenario ($)
A5: =COUNTIF('HC Detail'!$T$3:$T$22,"Technology")+COUNTIF('Non-HC Detail'!$D$3:$D$17,"Technology") -> 3 | C5: =SUMIF('Non-HC Detail'!$D$3:$D$17,"Technology",'Non-HC Detail'!$I$3:$I$17) -> 4620000 | E5: =SUMIF('Non-HC Detail'!$D$3:$D$17,"Technology",'Non-HC Detail'!$J$3:$J$17) -> 2430000 | G5: =SUMIF('Non-HC Detail'!$D$3:$D$17,"Technology",'Non-HC Detail'!$I$3:$I$17)-(SUMIF('Non-HC Detail'!$D$3:$D$17,"Technology",'Non-HC Detail'!$J$3:$J$17)) -> 2190000 | I5: =SUMIF('Non-HC Detail'!$D$3:$D$17,"Technology",'Non-HC Detail'!$L$3:$L$17) -> 1470000 | K5: =SUMIF('Non-HC Detail'!$D$3:$D$17,"Technology",'Non-HC Detail'!$I$3:$I$17) -> 4620000 | M5: =SUMIF('Non-HC Detail'!$D$3:$D$17,"Technology",'Non-HC Detail'!$I$3:$I$17)*1.15 -> 5313000
A7: INITIATIVE DETAIL — live from Non-HC Detail where Topic = 'Technology'
A8: Initiative ID | B8: Initiative Name | C8: Segment | D8: Owner | E8: P&L Line | F8: Status | G8: Gross Annual Savings ($) | H8: One-Time Cost ($) | I8: Net Annual Savings ($) | J8: Yr1 Realized ($) | K8: Run-Rate ($) | L8: Upside Scenario ($) | M8: Baseline Scenario ($) | N8: Notes
A9: I-020 | B9: ERP System Consolidation | C9: BH | D9: CIO | E9: SGA | F9: Pipeline | G9: 1400000 | H9: 2200000 | I9: -800000 | J9: 140000 | K9: 1400000 | L9: 1609999 | M9: 1190000
A10: I-021 | B10: Software License Rationalization | C10: GY | D10: CIO | E10: SGA | F10: Active | G10: 420000 | H10: 30000 | I10: 390000 | J10: 210000 | K10: 420000 | L10: 482999 | M10: 357000
A11: I-022 | B11: R&D Portfolio Prioritization | C11: Dx | D11: CSO | E11: RD | F11: Active | G11: 2800000 | H11: 200000 | I11: 2600000 | J11: 1120000 | K11: 2800000 | L11: 3219999 | M11: 2380000
A12: TOTALS — from Initiative Log | G12: =SUM(G9:G11) -> 4620000 | H12: =SUM(H9:H11) -> 2430000 | I12: =SUM(I9:I11) -> 2190000 | J12: =SUM(J9:J11) -> 1470000 | K12: =SUM(K9:K11) -> 4620000 | L12: =SUM(L9:L11) -> 5312997 | M12: =SUM(M9:M11) -> 3927000
A14: SCENARIO ANALYSIS — TECHNOLOGY (Upside / Base / Downside)
A15: Scenario | B15: Description | C15: Gross Savings ($) | D15: vs. Plan ($) | E15: vs. Plan (%) | F15: One-Time ($) | G15: Net Savings ($) | H15: Key Assumptions
A16: Upside | B16: Full capture; all Active, above plan | C16: 5313000 | D16: =C16-4620000 -> 693000 | E16: =IFERROR(C16/4620000-1,"-") -> 0.15 | F16: 2187000 | G16: =C16-F16 -> 3126000 | H16: Full execution; procurement/vendor beats target; no timeline slippage
A17: Base Plan | B17: Current plan; Active + Pipeline mix | C17: 4620000 | D17: =C17-4620000 -> 0 | E17: =IFERROR(C17/4620000-1,"-") -> 0 | F17: 2430000 | G17: =C17-F17 -> 2190000 | H17: Current initiative slate; on-schedule execution; no scope changes
A18: Downside | B18: Partial capture; delays, scope cuts | C18: 3465000 | D18: =C18-4620000 -> -1155000 | E18: =IFERROR(C18/4620000-1,"-") -> -0.25 | F18: 2673000 | G18: =C18-F18 -> 792000 | H18: 3-4 initiatives delayed; savings reduced 25%; facility timeline slip

Sheet Distribution Summary
A1: COMPANY A | Distribution | Value Creation Summary — All data from detail tabs
A3: KEY METRICS — DISTRIBUTION (formulas pull from HC Detail + Non-HC Detail tabs)
A4: # Initiatives | C4: Gross Annual Savings ($) | E4: One-Time Costs ($) | G4: Net Annual Savings ($) | I4: Year 1 Realized ($) | K4: Run-Rate (Yr3) ($) | M4: Upside Scenario ($)
A5: =COUNTIF('HC Detail'!$T$3:$T$22,"Distribution")+COUNTIF('Non-HC Detail'!$D$3:$D$17,"Distribution") -> 2 | C5: =SUMIF('Non-HC Detail'!$D$3:$D$17,"Distribution",'Non-HC Detail'!$I$3:$I$17) -> 1100000 | E5: =SUMIF('Non-HC Detail'!$D$3:$D$17,"Distribution",'Non-HC Detail'!$J$3:$J$17) -> 160000 | G5: =SUMIF('Non-HC Detail'!$D$3:$D$17,"Distribution",'Non-HC Detail'!$I$3:$I$17)-(SUMIF('Non-HC Detail'!$D$3:$D$17,"Distribution",'Non-HC Detail'!$J$3:$J$17)) -> 940000 | I5: =SUMIF('Non-HC Detail'!$D$3:$D$17,"Distribution",'Non-HC Detail'!$L$3:$L$17) -> 406000 | K5: =SUMIF('Non-HC Detail'!$D$3:$D$17,"Distribution",'Non-HC Detail'!$I$3:$I$17) -> 1100000 | M5: =SUMIF('Non-HC Detail'!$D$3:$D$17,"Distribution",'Non-HC Detail'!$I$3:$I$17)*1.15 -> 1265000
A7: INITIATIVE DETAIL — live from Non-HC Detail where Topic = 'Distribution'
A8: Initiative ID | B8: Initiative Name | C8: Segment | D8: Owner | E8: P&L Line | F8: Status | G8: Gross Annual Savings ($) | H8: One-Time Cost ($) | I8: Net Annual Savings ($) | J8: Yr1 Realized ($) | K8: Run-Rate ($) | L8: Upside Scenario ($) | M8: Baseline Scenario ($) | N8: Notes
A9: I-016 | B9: 3PL Contract Renegotiation | C9: Dx | D9: COO | E9: COGS | F9: Active | G9: 620000 | H9: 40000 | I9: 580000 | J9: 310000 | K9: 620000 | L9: 713000 | M9: 527000
A10: I-017 | B10: Logistics Network Optimization | C10: BH | D10: COO | E10: COGS | F10: Pipeline | G10: 480000 | H10: 120000 | I10: 360000 | J10: 96000 | K10: 480000 | L10: 552000 | M10: 408000
A11: TOTALS — from Initiative Log | G11: =SUM(G9:G10) -> 1100000 | H11: =SUM(H9:H10) -> 160000 | I11: =SUM(I9:I10) -> 940000 | J11: =SUM(J9:J10) -> 406000 | K11: =SUM(K9:K10) -> 1100000 | L11: =SUM(L9:L10) -> 1265000 | M11: =SUM(M9:M10) -> 935000
A13: SCENARIO ANALYSIS — DISTRIBUTION (Upside / Base / Downside)
A14: Scenario | B14: Description | C14: Gross Savings ($) | D14: vs. Plan ($) | E14: vs. Plan (%) | F14: One-Time ($) | G14: Net Savings ($) | H14: Key Assumptions
A15: Upside | B15: Full capture; all Active, above plan | C15: 1265000 | D15: =C15-1100000 -> 165000 | E15: =IFERROR(C15/1100000-1,"-") -> 0.15 | F15: 144000 | G15: =C15-F15 -> 1121000 | H15: Full execution; procurement/vendor beats target; no timeline slippage
A16: Base Plan | B16: Current plan; Active + Pipeline mix | C16: 1100000 | D16: =C16-1100000 -> 0 | E16: =IFERROR(C16/1100000-1,"-") -> 0 | F16: 160000 | G16: =C16-F16 -> 940000 | H16: Current initiative slate; on-schedule execution; no scope changes
A17: Downside | B17: Partial capture; delays, scope cuts | C17: 825000 | D17: =C17-1100000 -> -275000 | E17: =IFERROR(C17/1100000-1,"-") -> -0.25 | F17: 176000 | G17: =C17-F17 -> 649000 | H17: 3-4 initiatives delayed; savings reduced 25%; facility timeline slip

Sheet Public-to-Private Summary
A1: COMPANY A | Public-to-Private | Value Creation Summary — All data from detail tabs
A3: KEY METRICS — PUBLIC-TO-PRIVATE (formulas pull from HC Detail + Non-HC Detail tabs)
A4: # Initiatives | C4: Gross Annual Savings ($) | E4: One-Time Costs ($) | G4: Net Annual Savings ($) | I4: Year 1 Realized ($) | K4: Run-Rate (Yr3) ($) | M4: Upside Scenario ($)
A5: =COUNTIF('HC Detail'!$T$3:$T$22,"Public-to-Private")+COUNTIF('Non-HC Detail'!$D$3:$D$17,"Public-to-Private") -> 2 | C5: =SUMIF('Non-HC Detail'!$D$3:$D$17,"Public-to-Private",'Non-HC Detail'!$I$3:$I$17) -> 1860000 | E5: =SUMIF('Non-HC Detail'!$D$3:$D$17,"Public-to-Private",'Non-HC Detail'!$J$3:$J$17) -> 180000 | G5: =SUMIF('Non-HC Detail'!$D$3:$D$17,"Public-to-Private",'Non-HC Detail'!$I$3:$I$17)-(SUMIF('Non-HC Detail'!$D$3:$D$17,"Public-to-Private",'Non-HC Detail'!$J$3:$J$17)) -> 1680000 | I5: =SUMIF('Non-HC Detail'!$D$3:$D$17,"Public-to-Private",'Non-HC Detail'!$L$3:$L$17) -> 1480000 | K5: =SUMIF('Non-HC Detail'!$D$3:$D$17,"Public-to-Private",'Non-HC Detail'!$I$3:$I$17) -> 1860000 | M5: =SUMIF('Non-HC Detail'!$D$3:$D$17,"Public-to-Private",'Non-HC Detail'!$I$3:$I$17)*1.15 -> 2139000
A7: INITIATIVE DETAIL — live from Non-HC Detail where Topic = 'Public-to-Private'
A8: Initiative ID | B8: Initiative Name | C8: Segment | D8: Owner | E8: P&L Line | F8: Status | G8: Gross Annual Savings ($) | H8: One-Time Cost ($) | I8: Net Annual Savings ($) | J8: Yr1 Realized ($) | K8: Run-Rate ($) | L8: Upside Scenario ($) | M8: Baseline Scenario ($) | N8: Notes
A9: I-023 | B9: Office Lease Termination | C9: BH | D9: CFO | E9: SGA | F9: Active | G9: 760000 | H9: 180000 | I9: 580000 | J9: 380000 | K9: 760000 | L9: 873999 | M9: 646000
A10: I-024 | B10: Public Co. Cost Elimination | C10: GY | D10: CFO | E10: SGA | F10: Complete | G10: 1100000 | H10: 0 | I10: 1100000 | J10: 1100000 | K10: 1100000 | L10: 1265000 | M10: 935000
A11: TOTALS — from Initiative Log | G11: =SUM(G9:G10) -> 1860000 | H11: =SUM(H9:H10) -> 180000 | I11: =SUM(I9:I10) -> 1680000 | J11: =SUM(J9:J10) -> 1480000 | K11: =SUM(K9:K10) -> 1860000 | L11: =SUM(L9:L10) -> 2138999 | M11: =SUM(M9:M10) -> 1581000
A13: SCENARIO ANALYSIS — PUBLIC-TO-PRIVATE (Upside / Base / Downside)
A14: Scenario | B14: Description | C14: Gross Savings ($) | D14: vs. Plan ($) | E14: vs. Plan (%) | F14: One-Time ($) | G14: Net Savings ($) | H14: Key Assumptions
A15: Upside | B15: Full capture; all Active, above plan | C15: 2139000 | D15: =C15-1860000 -> 279000 | E15: =IFERROR(C15/1860000-1,"-") -> 0.15 | F15: 162000 | G15: =C15-F15 -> 1977000 | H15: Full execution; procurement/vendor beats target; no timeline slippage
A16: Base Plan | B16: Current plan; Active + Pipeline mix | C16: 1860000 | D16: =C16-1860000 -> 0 | E16: =IFERROR(C16/1860000-1,"-") -> 0 | F16: 180000 | G16: =C16-F16 -> 1680000 | H16: Current initiative slate; on-schedule execution; no scope changes
A17: Downside | B17: Partial capture; delays, scope cuts | C17: 1395000 | D17: =C17-1860000 -> -465000 | E17: =IFERROR(C17/1860000-1,"-") -> -0.25 | F17: 198000 | G17: =C17-F17 -> 1197000 | H17: 3-4 initiatives delayed; savings reduced 25%; facility timeline slip

Sheet P&L Bridge & Valuation
A1: COMPANY A | P&L Bridge & Valuation | PE Cost Transformation — Finance Model
A2: Blue = Input · Black = Formula · Green = Cross-sheet link from detail tabs · All $ in actual unless stated $mm
A4: SECTION 1 — COST SAVINGS BY P&L LINE (live from HC Detail + Non-HC Detail)
A5: P&L Line | B5: Topics Included | C5: # Initiatives | D5: Gross Annual Savings ($) | E5: One-Time Costs ($) | F5: Net Annual Savings ($) | G5: Yr1 Realized Savings ($) | H5: Yr2 Savings ($) | I5: Yr3 Run-Rate ($) | J5: % of Total Savings
A6: COGS | B6: Manufacturing · Procurement · Distribution | C6: =COUNTIF('HC Detail'!$U$3:$U$22,"COGS")+COUNTIF('Non-HC Detail'!$V$3:$V$17,"COGS") -> 7 | D6: =SUMPRODUCT(('HC Detail'!$U$3:$U$22="COGS")*('HC Detail'!$Q$3:$Q$22))+SUMPRODUCT(('Non-HC Detail'!$V$3:$V$17="COGS")*('Non-HC Detail'!$I$3:$I$17)) -> 12325000 | E6: =SUMPRODUCT(('HC Detail'!$U$3:$U$22="COGS")*('HC Detail'!$P$3:$P$22))+SUMPRODUCT(('Non-HC Detail'!$V$3:$V$17="COGS")*('Non-HC Detail'!$J$3:$J$17)) -> 3190000 | F6: =D6-E6 -> 9135000 | G6: =SUMPRODUCT(('HC Detail'!$U$3:$U$22="COGS")*('HC Detail'!$R$3:$R$22))+SUMPRODUCT(('Non-HC Detail'!$V$3:$V$17="COGS")*('Non-HC Detail'!$L$3:$L$17)) -> 4176000 | H6: =D6*0.9 -> 11092500 | I6: =D6 -> 12325000 | J6: =IFERROR(D6/D9,"-") -> 0.51026745
A7: SGA | B7: G&A / HC · Marketing · Technology · Public-to-Private · T&E | C7: =COUNTIF('HC Detail'!$U$3:$U$22,"SGA")+COUNTIF('Non-HC Detail'!$V$3:$V$17,"SGA") -> 27 | D7: =SUMPRODUCT(('HC Detail'!$U$3:$U$22="SGA")*('HC Detail'!$Q$3:$Q$22))+SUMPRODUCT(('Non-HC Detail'!$V$3:$V$17="SGA")*('Non-HC Detail'!$I$3:$I$17)) -> 9029000 | E7: =SUMPRODUCT(('HC Detail'!$U$3:$U$22="SGA")*('HC Detail'!$P$3:$P$22))+SUMPRODUCT(('Non-HC Detail'!$V$3:$V$17="SGA")*('Non-HC Detail'!$J$3:$J$17)) -> 3700115.4 | F7: =D7-E7 -> 5328884.6 | G7: =SUMPRODUCT(('HC Detail'!$U$3:$U$22="SGA")*('HC Detail'!$R$3:$R$22))+SUMPRODUCT(('Non-HC Detail'!$V$3:$V$17="SGA")*('Non-HC Detail'!$L$3:$L$17)) -> 4209525 | H7: =D7*0.9 -> 8126100 | I7: =D7 -> 9029000 | J7: =IFERROR(D7/D9,"-") -> 0.37380972
A8: RD | B8: Technology (R&D Portfolio) | C8: =COUNTIF('HC Detail'!$U$3:$U$22,"RD")+COUNTIF('Non-HC Detail'!$V$3:$V$17,"RD") -> 1 | D8: =SUMPRODUCT(('HC Detail'!$U$3:$U$22="RD")*('HC Detail'!$Q$3:$Q$22))+SUMPRODUCT(('Non-HC Detail'!$V$3:$V$17="RD")*('Non-HC Detail'!$I$3:$I$17)) -> 2800000 | E8: =SUMPRODUCT(('HC Detail'!$U$3:$U$22="RD")*('HC Detail'!$P$3:$P$22))+SUMPRODUCT(('Non-HC Detail'!$V$3:$V$17="RD")*('Non-HC Detail'!$J$3:$J$17)) -> 200000 | F8: =D8-E8 -> 2600000 | G8: =SUMPRODUCT(('HC Detail'!$U$3:$U$22="RD")*('HC Detail'!$R$3:$R$22))+SUMPRODUCT(('Non-HC Detail'!$V$3:$V$17="RD")*('Non-HC Detail'!$L$3:$L$17)) -> 1120000 | H8: =D8*0.9 -> 2520000 | I8: =D8 -> 2800000 | J8: =IFERROR(D8/D9,"-") -> 0.11592283
A9: TOTAL | C9: =SUM(C6:C8) -> 35 | D9: =SUM(D6:D8) -> 24154000 | E9: =SUM(E6:E8) -> 7090115.4 | F9: =SUM(F6:F8) -> 17063885 | G9: =SUM(G6:G8) -> 9505525 | H9: =SUM(H6:H8) -> 21738600 | I9: =SUM(I6:I8) -> 24154000 | J9: 100.0%
A11: SECTION 2 — P&L BRIDGE (Enter Baseline Below — Finance Adjusts | Blue = Input)
A12: Baseline Revenue ($) | C12: 850000000
A13: Baseline COGS ($) | C13: -520000000
A14: Baseline SG&A ($) | C14: -185000000
A15: Baseline R&D ($) | C15: -68000000
A17: Line Item | B17: P&L Category | C17: Baseline ($) | D17: Cost Savings (Plan) ($) | E17: Post-Transform Forecast ($) | F17: $ Change | G17: % Change | H17: Yr1 Savings ($) | I17: Yr2 Savings ($) | J17: Yr3 Run-Rate ($)
A18: Revenue | B18: Revenue | C18: =C12 -> 850000000 | D18: 0 | E18: =C18+D18 -> 850000000 | F18: =E18-C18 -> 0 | G18: =IFERROR(F18/ABS(C18),0) -> 0 | H18: 0 | I18: 0 | J18: 0
A19: Cost of Goods Sold | B19: COGS | C19: =C13 -> -520000000 | D19: =D6 -> 12325000 | E19: =C19+D19 -> -507675000 | F19: =E19-C19 -> 12325000 | G19: =IFERROR(F19/ABS(C19),0) -> 0.023701923 | H19: =G6 -> 4176000 | I19: =H6 -> 11092500 | J19: =I6 -> 12325000
A20: Gross Profit | B20: GP | C20: =C18+C19 -> 330000000 | E20: =E18+E19 -> 342325000 | F20: =E20-C20 -> 12325000 | G20: =IFERROR(F20/ABS(C20),0) -> 0.037348485 | H20: =H19 -> 4176000 | I20: =I19 -> 11092500 | J20: =J19 -> 12325000
A21: Gross Margin % | B21: GM% | C21: =IFERROR(C20/C18,0) -> 0.38823529 | E21: =IFERROR(E20/E18,0) -> 0.40273529 | F21: =E21-C21 -> 0.0145
A22: SG&A | B22: SGA | C22: =C14 -> -185000000 | D22: =D7 -> 9029000 | E22: =C22+D22 -> -175971000 | F22: =E22-C22 -> 9029000 | G22: =IFERROR(F22/ABS(C22),0) -> 0.048805405 | H22: =G7 -> 4209525 | I22: =H7 -> 8126100 | J22: =I7 -> 9029000
A23: R&D | B23: RD | C23: =C15 -> -68000000 | D23: =D8 -> 2800000 | E23: =C23+D23 -> -65200000 | F23: =E23-C23 -> 2800000 | G23: =IFERROR(F23/ABS(C23),0) -> 0.041176471 | H23: =G8 -> 1120000 | I23: =H8 -> 2520000 | J23: =I8 -> 2800000
A24: EBITDA | B24: EBITDA | C24: =C18+C19+C22+C23 -> 77000000 | E24: =E18+E19+E22+E23 -> 101154000 | F24: =E24-C24 -> 24154000 | G24: =IFERROR(F24/ABS(C24),0) -> 0.31368831 | H24: =H19+H22+H23 -> 9505525 | I24: =I19+I22+I23 -> 21738600 | J24: =J19+J22+J23 -> 24154000
A25: EBITDA Margin % | B25: EBITDA% | C25: =IFERROR(C24/C18,0) -> 0.090588235 | E25: =IFERROR(E24/E18,0) -> 0.11900471 | F25: =E25-C25 -> 0.028416471
A28: SECTION 3 — VALUATION ASSUMPTIONS (Blue = Input)
A29: Entry EBITDA ($mm) | B29: Entry EBITDA at acquisition — pre-transformation | C29: 85 | D29: $mm
A30: Entry EV/EBITDA Multiple (x) | B30: Entry multiple paid at acquisition | C30: 12.5 | D30: x
A31: Run-Rate EBITDA Uplift ($mm) | B31: Total run-rate savings → EBITDA (from Section 1) | C31: =I9/1000000 -> 24.154 | D31: formula
A32: Revised EBITDA ($mm) | B32: Entry EBITDA + run-rate savings uplift | C32: =C29+C31 -> 109.154 | D32: formula
A33: Net Debt at Entry ($mm) | B33: Total net debt at time of acquisition | C33: 420 | D33: $mm
A34: Mgmt / Co-Invest Equity % (%) | B34: Management & co-invest share of equity | C34: 10 | D34: %
A35: Hold Period (yrs) | B35: Expected PE hold period | C35: 5 | D35: yrs
A36: Revenue Growth CAGR (%) | B36: Assumed organic revenue growth over hold | C36: 4 | D36: %
A37: EBITDA Margin Expansion (pp) | B37: Additional margin expansion beyond cost savings | C37: 1.5 | D37: pp
A40: SECTION 4 — PE VALUATION SCENARIOS | 3-Case Model (Downside / Base / Upside)
A41: Exit Multiple Assumptions (Input):
A42: Exit Multiple — Downside (x) | B42: 11.5
A43: Exit Multiple — Base (x) | B43: 13
A44: Exit Multiple — Upside (x) | B44: 14.5
A45: EBITDA Savings Capture — Downside (%) | B45: 0.75
A46: EBITDA Savings Capture — Base (%) | B46: 1
A47: EBITDA Savings Capture — Upside (%) | B47: 1
...

Sheet Initiative Log
A1: COMPANY A | Initiative Log | Master Raw Data — All Other Tabs Pull From Here
A2: Initiative ID | B2: BU | C2: Segment (Dx/BH/GY) | D2: Category (HC/Non-HC) | E2: Topic | F2: Sub-Category | G2: Initiative Name | H2: Owner | I2: Department | J2: GL Code | K2: Description | L2: Status | M2: Start Date | N2: End Date | O2: Baseline ($) | P2: Gross Annual Savings ($) | Q2: One-Time Cost ($) | R2: Upside Target ($) | S2: Yr1 % | T2: Yr2 % | U2: Yr3 % | V2: P&L Line (COGS/SGA/RD) | W2: Notes
A3: I-001 | B3: Corp | C3: Dx | D3: HC | E3: G&A / HC | F3: Executive | G3: VP Molecular Dx Elimination | H3: CFO | I3: Executive | J3: 6100 | K3: Elim VP Molecular Dx post-acq | L3: Active | M3: 2025-01-01 | N3: 2025-03-31 | O3: 320000 | P3: 320000 | Q3: 45000 | R3: 300000 | S3: 0.5 | T3: 1 | U3: 1 | V3: SGA
A4: I-002 | B4: Corp | C4: Dx | D4: HC | E4: G&A / HC | F4: Director | G4: Director Clinical Affairs Reduction | H4: CHRO | I4: Clinical Affairs | J4: 6100 | K4: Consolidate two Director roles | L4: Active | M4: 2025-01-01 | N4: 2025-06-30 | O4: 385000 | P4: 385000 | Q4: 65000 | R4: 370000 | S4: 0.4 | T4: 1 | U4: 1 | V4: SGA
A5: I-003 | B5: Corp | C5: BH | D5: HC | E5: G&A / HC | F5: Manager | G5: Regional Sales Manager Reduction (3) | H5: CSO | I5: Sales | J5: 6110 | K5: RSM headcount -3, territory consol | L5: Active | M5: 2025-02-01 | N5: 2025-06-30 | O5: 480000 | P5: 480000 | Q5: 60000 | R5: 450000 | S5: 0.5 | T5: 1 | U5: 1 | V5: SGA
A6: I-004 | B6: Corp | C6: BH | D6: HC | E6: G&A / HC | F6: IC | G6: Field Service Engineer Optimization (2) | H6: COO | I6: Field Service | J6: 6110 | K6: FSE reduction via territory consol | L6: Pipeline | M6: 2025-04-01 | N6: 2025-09-30 | O6: 275000 | P6: 275000 | Q6: 35000 | R6: 260000 | S6: 0.2 | T6: 0.8 | U6: 1 | V6: SGA
A7: I-005 | B7: Corp | C7: GY | D7: HC | E7: G&A / HC | F7: Manager | G7: GYN Surgical Marketing Manager | H7: CMO | I7: Marketing | J7: 6120 | K7: Elim GYN Surgical Marketing Mgr | L7: Active | M7: 2025-01-01 | N7: 2025-03-31 | O7: 185000 | P7: 185000 | Q7: 25000 | R7: 175000 | S7: 0.5 | T7: 1 | U7: 1 | V7: SGA
A8: I-006 | B8: Corp | C8: GY | D8: HC | E8: G&A / HC | F8: IC | G8: Inside Sales Rep Reduction (4) | H8: CSO | I8: Sales | J8: 6120 | K8: Inside sales -4 FTEs | L8: Pipeline | M8: 2025-05-01 | N8: 2025-10-31 | O8: 340000 | P8: 340000 | Q8: 50000 | R8: 320000 | S8: 0.2 | T8: 0.8 | U8: 1 | V8: SGA
A9: I-007 | B9: Shared | C9: Dx | D9: HC | E9: G&A / HC | F9: IC | G9: Regulatory Affairs Reduction (2) | H9: CLO | I9: Regulatory | J9: 6130 | K9: Consolidate RA function post-acq | L9: Active | M9: 2025-02-01 | N9: 2025-07-31 | O9: 260000 | P9: 260000 | Q9: 30000 | R9: 250000 | S9: 0.4 | T9: 1 | U9: 1 | V9: SGA
A10: I-008 | B10: Shared | C10: BH | D10: HC | E10: G&A / HC | F10: Director | G10: Director Quality Systems Consol | H10: COO | I10: Quality | J10: 6130 | K10: Merge BH+Dx Quality Director | L10: Active | M10: 2025-01-01 | N10: 2025-04-30 | O10: 230000 | P10: 230000 | Q10: 35000 | R10: 220000 | S10: 0.5 | T10: 1 | U10: 1 | V10: SGA
A11: I-009 | B11: Shared | C11: GY | D11: HC | E11: G&A / HC | F11: IC | G11: Finance Analyst Reduction (2) | H11: CFO | I11: Finance | J11: 6140 | K11: Finance analyst pool -2 FTEs | L11: Complete | M11: 2025-01-01 | N11: 2025-02-28 | O11: 180000 | P11: 180000 | Q11: 20000 | R11: 175000 | S11: 1 | T11: 1 | U11: 1 | V11: SGA
A12: I-010 | B12: Corp | C12: Dx | D12: HC | E12: G&A / HC | F12: IC | G12: IT Infrastructure Staff Reduction (2) | H12: CIO | I12: IT | J12: 6140 | K12: IT headcount after system consol | L12: Pipeline | M12: 2025-06-01 | N12: 2025-12-31 | O12: 210000 | P12: 210000 | Q12: 40000 | R12: 200000 | S12: 0.2 | T12: 0.8 | U12: 1 | V12: SGA
A13: I-011 | B13: Mfg | C13: Dx | D13: Non-HC | E13: Manufacturing | F13: Facility | G13: San Diego Mfg Plant Closure | H13: COO | I13: Manufacturing | J13: 7100 | K13: Full closure SD site, transfer to MA | L13: Active | M13: 2025-03-01 | N13: 2026-06-30 | O13: 4200000 | P13: 4200000 | Q13: 1800000 | R13: 4000000 | S13: 0.3 | T13: 0.8 | U13: 1 | V13: COGS
A14: I-012 | B14: Mfg | C14: BH | D14: Non-HC | E14: Manufacturing | F14: Facility | G14: Marlborough Facility Consolidation | H14: COO | I14: Manufacturing | J14: 7100 | K14: Consolidate two Marlborough sites | L14: Pipeline | M14: 2025-07-01 | N14: 2026-12-31 | O14: 1850000 | P14: 1850000 | Q14: 950000 | R14: 1750000 | S14: 0.1 | T14: 0.6 | U14: 1 | V14: COGS
... A27: I-025 | B27: Shared | C27: BH | D27: Non-HC | E27: G&A / HC | F27: T&E Policy | G27: Travel & Expense Policy Tightening | H27: CFO | I27: Finance | J27: 7900 | K27: New T&E policy -30% | L27: Active | M27: 2025-01-01 | N27: 2025-06-30 | O27: 480000 | P27: 480000 | Q27: 25000 | R27: 460000 | S27: 0.5 | T27: 1 | U27: 1 | V27: SGA
A28: TOTALS | P28: =SUM(P3:P27) -> 23480000 | Q28: =SUM(Q3:Q27) -> 6425000 | R28: =SUM(R3:R27) -> 22460000

Sheet HC Detail
A1: COMPANY A | HC Detail | Manual Input Rows → Auto-Tag Columns Pull from Initiative Log
A2: Initiative ID | B2: Segment | C2: Department | D2: Employee / Position | E2: Job Title | F2: Level | G2: FTE | H2: Base Salary ($) | I2: Bonus ($) | J2: Total Cash ($) | K2: Benefits & Payroll Tax ($) | L2: Total Annual Comp ($) | M2: Severance (Wks) | N2: Severance Amt ($) | O2: Outplacement ($) | P2: Total One-Time Cost ($) | Q2: Gross Annual Saving ($) | R2: Yr1 Realized Saving ($) | S2: Run-Rate Annual Saving ($) | T2: Topic [auto] | U2: P&L Line [auto] | V2: Status [auto] | W2: Owner [auto] | X2: Segment Tag [auto]
A3: I-001 | B3: Dx | C3: Executive | D3: [Position Eliminated] | E3: VP Molecular Diagnostics | F3: Exec | G3: 1 | H3: 280000 | I3: 42000 | J3: =H3+I3 -> 322000 | K3: =J3*0.25 -> 80500 | L3: =J3+K3 -> 402500 | M3: 52 | N3: =(H3/52)*M3 -> 280000 | O3: 15000 | P3: =N3+O3 -> 295000 | Q3: =L3 -> 402500 | R3: =IFERROR(Q3*VLOOKUP(A3,'Initiative Log'!$A:$S,19,0),0) -> 201250 | S3: =Q3 -> 402500 | T3: =IFERROR(VLOOKUP(A3,'Initiative Log'!$A:$E,5,0),"") -> G&A / HC | U3: =IFERROR(VLOOKUP(A3,'Initiative Log'!$A:$V,22,0),"") -> SGA | V3: =IFERROR(VLOOKUP(A3,'Initiative Log'!$A:$L,12,0),"") -> Active | W3: =IFERROR(VLOOKUP(A3,'Initiative Log'!$A:$H,8,0),"") -> CFO | X3: =IFERROR(VLOOKUP(A3,'Initiative Log'!$A:$C,3,0),"") -> Dx
A4: I-002 | B4: Dx | C4: Clinical Affairs | D4: [Position Eliminated] | E4: Director Clinical Affairs | F4: Dir | G4: 1 | H4: 185000 | I4: 27750 | J4: =H4+I4 -> 212750 | K4: =J4*0.25 -> 53187.5 | L4: =J4+K4 -> 265937.5 | M4: 26 | N4: =(H4/52)*M4 -> 92500 | O4: 8000 | P4: =N4+O4 -> 100500 | Q4: =L4 -> 265937.5 | R4: =IFERROR(Q4*VLOOKUP(A4,'Initiative Log'!$A:$S,19,0),0) -> 106375 | S4: =Q4 -> 265937.5 | T4: =IFERROR(VLOOKUP(A4,'Initiative Log'!$A:$E,5,0),"") -> G&A / HC | U4: =IFERROR(VLOOKUP(A4,'Initiative Log'!$A:$V,22,0),"") -> SGA | V4: =IFERROR(VLOOKUP(A4,'Initiative Log'!$A:$L,12,0),"") -> Active | W4: =IFERROR(VLOOKUP(A4,'Initiative Log'!$A:$H,8,0),"") -> CHRO | X4: =IFERROR(VLOOKUP(A4,'Initiative Log'!$A:$C,3,0),"") -> Dx
A5: I-002 | B5: Dx | C5: Clinical Affairs | D5: [Position Consolidated] | E5: Director Clinical Operations | F5: Dir | G5: 1 | H5: 175000 | I5: 21000 | J5: =H5+I5 -> 196000 | K5: =J5*0.25 -> 49000 | L5: =J5+K5 -> 245000 | M5: 26 | N5: =(H5/52)*M5 -> 87500 | O5: 8000 | P5: =N5+O5 -> 95500 | Q5: =L5 -> 245000 | R5: =IFERROR(Q5*VLOOKUP(A5,'Initiative Log'!$A:$S,19,0),0) -> 98000 | S5: =Q5 -> 245000 | T5: =IFERROR(VLOOKUP(A5,'Initiative Log'!$A:$E,5,0),"") -> G&A / HC | U5: =IFERROR(VLOOKUP(A5,'Initiative Log'!$A:$V,22,0),"") -> SGA | V5: =IFERROR(VLOOKUP(A5,'Initiative Log'!$A:$L,12,0),"") -> Active | W5: =IFERROR(VLOOKUP(A5,'Initiative Log'!$A:$H,8,0),"") -> CHRO | X5: =IFERROR(VLOOKUP(A5,'Initiative Log'!$A:$C,3,0),"") -> Dx
A6: I-003 | B6: BH | C6: Sales | D6: [Position Eliminated] | E6: Regional Sales Manager - East | F6: Mgr | G6: 1 | H6: 135000 | I6: 27000 | J6: =H6+I6 -> 162000 | K6: =J6*0.25 -> 40500 | L6: =J6+K6 -> 202500 | M6: 16 | N6: =(H6/52)*M6 -> 41538.462 | O6: 5000 | P6: =N6+O6 -> 46538.462 | Q6: =L6 -> 202500 | R6: =IFERROR(Q6*VLOOKUP(A6,'Initiative Log'!$A:$S,19,0),0) -> 101250 | S6: =Q6 -> 202500 | T6: =IFERROR(VLOOKUP(A6,'Initiative Log'!$A:$E,5,0),"") -> G&A / HC | U6: =IFERROR(VLOOKUP(A6,'Initiative Log'!$A:$V,22,0),"") -> SGA | V6: =IFERROR(VLOOKUP(A6,'Initiative Log'!$A:$L,12,0),"") -> Active | W6: =IFERROR(VLOOKUP(A6,'Initiative Log'!$A:$H,8,0),"") -> CSO | X6: =IFERROR(VLOOKUP(A6,'Initiative Log'!$A:$C,3,0),"") -> BH
A7: I-003 | B7: BH | C7: Sales | D7: [Position Eliminated] | E7: Regional Sales Manager - Central | F7: Mgr | G7: 1 | H7: 130000 | I7: 26000 | J7: =H7+I7 -> 156000 | K7: =J7*0.25 -> 39000 | L7: =J7+K7 -> 195000 | M7: 16 | N7: =(H7/52)*M7 -> 40000 | O7: 5000 | P7: =N7+O7 -> 45000 | Q7: =L7 -> 195000 | R7: =IFERROR(Q7*VLOOKUP(A7,'Initiative Log'!$A:$S,19,0),0) -> 97500 | S7: =Q7 -> 195000 | T7: =IFERROR(VLOOKUP(A7,'Initiative Log'!$A:$E,5,0),"") -> G&A / HC | U7: =IFERROR(VLOOKUP(A7,'Initiative Log'!$A:$V,22,0),"") -> SGA | V7: =IFERROR(VLOOKUP(A7,'Initiative Log'!$A:$L,12,0),"") -> Active | W7: =IFERROR(VLOOKUP(A7,'Initiative Log'!$A:$H,8,0),"") -> CSO | X7: =IFERROR(VLOOKUP(A7,'Initiative Log'!$A:$C,3,0),"") -> BH
A8: I-003 | B8: BH | C8: Sales | D8: [Position Eliminated] | E8: Regional Sales Manager - West | F8: Mgr | G8: 1 | H8: 140000 | I8: 28000 | J8: =H8+I8 -> 168000 | K8: =J8*0.25 -> 42000 | L8: =J8+K8 -> 210000 | M8: 16 | N8: =(H8/52)*M8 -> 43076.923 | O8: 5000 | P8: =N8+O8 -> 48076.923 | Q8: =L8 -> 210000 | R8: =IFERROR(Q8*VLOOKUP(A8,'Initiative Log'!$A:$S,19,0),0) -> 105000 | S8: =Q8 -> 210000 | T8: =IFERROR(VLOOKUP(A8,'Initiative Log'!$A:$E,5,0),"") -> G&A / HC | U8: =IFERROR(VLOOKUP(A8,'Initiative Log'!$A:$V,22,0),"") -> SGA | V8: =IFERROR(VLOOKUP(A8,'Initiative Log'!$A:$L,12,0),"") -> Active | W8: =IFERROR(VLOOKUP(A8,'Initiative Log'!$A:$H,8,0),"") -> CSO | X8: =IFERROR(VLOOKUP(A8,'Initiative Log'!$A:$C,3,0),"") -> BH
A9: I-004 | B9: BH | C9: Field Service | D9: [Position Eliminated] | E9: Field Service Engineer Sr. | F9: IC | G9: 1 | H9: 110000 | I9: 11000 | J9: =H9+I9 -> 121000 | K9: =J9*0.25 -> 30250 | L9: =J9+K9 -> 151250 | M9: 12 | N9: =(H9/52)*M9 -> 25384.615 | O9: 2500 | P9: =N9+O9 -> 27884.615 | Q9: =L9 -> 151250 | R9: =IFERROR(Q9*VLOOKUP(A9,'Initiative Log'!$A:$S,19,0),0) -> 30250 | S9: =Q9 -> 151250 | T9: =IFERROR(VLOOKUP(A9,'Initiative Log'!$A:$E,5,0),"") -> G&A / HC | U9: =IFERROR(VLOOKUP(A9,'Initiative Log'!$A:$V,22,0),"") -> SGA | V9: =IFERROR(VLOOKUP(A9,'Initiative Log'!$A:$L,12,0),"") -> Pipeline | W9: =IFERROR(VLOOKUP(A9,'Initiative Log'!$A:$H,8,0),"") -> COO | X9: =IFERROR(VLOOKUP(A9,'Initiative Log'!$A:$C,3,0),"") -> BH
A10: I-004 | B10: BH | C10: Field Service | D10: [Position Eliminated] | E10: Field Service Engineer | F10: IC | G10: 1 | H10: 95000 | I10: 9500 | J10: =H10+I10 -> 104500 | K10: =J10*0.25 -> 26125 | L10: =J10+K10 -> 130625 | M10: 12 | N10: =(H10/52)*M10 -> 21923.077 | O10: 2500 | P10: =N10+O10 -> 24423.077 | Q10: =L10 -> 130625 | R10: =IFERROR(Q10*VLOOKUP(A10,'Initiative Log'!$A:$S,19,0),0) -> 26125 | S10: =Q10 -> 130625 | T10: =IFERROR(VLOOKUP(A10,'Initiative Log'!$A:$E,5,0),"") -> G&A / HC | U10: =IFERROR(VLOOKUP(A10,'Initiative Log'!$A:$V,22,0),"") -> SGA | V10: =IFERROR(VLOOKUP(A10,'Initiative Log'!$A:$L,12,0),"") -> Pipeline | W10: =IFERROR(VLOOKUP(A10,'Initiative Log'!$A:$H,8,0),"") -> COO | X10: =IFERROR(VLOOKUP(A10,'Initiative Log'!$A:$C,3,0),"") -> BH
A11: I-005 | B11: GY | C11: Marketing | D11: [Position Eliminated] | E11: Marketing Manager - GYN Surgical | F11: Mgr | G11: 1 | H11: 155000 | I11: 23250 | J11: =H11+I11 -> 178250 | K11: =J11*0.25 -> 44562.5 | L11: =J11+K11 -> 222812.5 | M11: 16 | N11: =(H11/52)*M11 -> 47692.308 | O11: 5000 | P11: =N11+O11 -> 52692.308 | Q11: =L11 -> 222812.5 | R11: =IFERROR(Q11*VLOOKUP(A11,'Initiative Log'!$A:$S,19,0),0) -> 111406.25 | S11: =Q11 -> 222812.5 | T11: =IFERROR(VLOOKUP(A11,'Initiative Log'!$A:$E,5,0),"") -> G&A / HC | U11: =IFERROR(VLOOKUP(A11,'Initiative Log'!$A:$V,22,0),"") -> SGA | V11: =IFERROR(VLOOKUP(A11,'Initiative Log'!$A:$L,12,0),"") -> Active | W11: =IFERROR(VLOOKUP(A11,'Initiative Log'!$A:$H,8,0),"") -> CMO | X11: =IFERROR(VLOOKUP(A11,'Initiative Log'!$A:$C,3,0),"") -> GY
A12: I-006 | B12: GY | C12: Sales | D12: [Position Eliminated] | E12: Inside Sales Rep | F12: IC | G12: 1 | H12: 72000 | I12: 10800 | J12: =H12+I12 -> 82800 | K12: =J12*0.25 -> 20700 | L12: =J12+K12 -> 103500 | M12: 12 | N12: =(H12/52)*M12 -> 16615.385 | O12: 2500 | P12: =N12+O12 -> 19115.385 | Q12: =L12 -> 103500 | R12: =IFERROR(Q12*VLOOKUP(A12,'Initiative Log'!$A:$S,19,0),0) -> 20700 | S12: =Q12 -> 103500 | T12: =IFERROR(VLOOKUP(A12,'Initiative Log'!$A:$E,5,0),"") -> G&A / HC | U12: =IFERROR(VLOOKUP(A12,'Initiative Log'!$A:$V,22,0),"") -> SGA | V12: =IFERROR(VLOOKUP(A12,'Initiative Log'!$A:$L,12,0),"") -> Pipeline | W12: =IFERROR(VLOOKUP(A12,'Initiative Log'!$A:$H,8,0),"") -> CSO | X12: =IFERROR(VLOOKUP(A12,'Initiative Log'!$A:$C,3,0),"") -> GY
A13: I-006 | B13: GY | C13: Sales | D13: [Position Eliminated] | E13: Inside Sales Rep | F13: IC | G13: 1 | H13: 68000 | I13: 10200 | J13: =H13+I13 -> 78200 | K13: =J13*0.25 -> 19550 | L13: =J13+K13 -> 97750 | M13: 12 | N13: =(H13/52)*M13 -> 15692.308 | O13: 2500 | P13: =N13+O13 -> 18192.308 | Q13: =L13 -> 97750 | R13: =IFERROR(Q13*VLOOKUP(A13,'Initiative Log'!$A:$S,19,0),0) -> 19550 | S13: =Q13 -> 97750 | T13: =IFERROR(VLOOKUP(A13,'Initiative Log'!$A:$E,5,0),"") -> G&A / HC | U13: =IFERROR(VLOOKUP(A13,'Initiative Log'!$A:$V,22,0),"") -> SGA | V13: =IFERROR(VLOOKUP(A13,'Initiative Log'!$A:$L,12,0),"") -> Pipeline | W13: =IFERROR(VLOOKUP(A13,'Initiative Log'!$A:$H,8,0),"") -> CSO | X13: =IFERROR(VLOOKUP(A13,'Initiative Log'!$A:$C,3,0),"") -> GY
A14: I-006 | B14: GY | C14: Sales | D14: [Position Eliminated] | E14: Inside Sales Rep | F14: IC | G14: 1 | H14: 70000 | I14: 10500 | J14: =H14+I14 -> 80500 | K14: =J14*0.25 -> 20125 | L14: =J14+K14 -> 100625 | M14: 12 | N14: =(H14/52)*M14 -> 16153.846 | O14: 2500 | P14: =N14+O14 -> 18653.846 | Q14: =L14 -> 100625 | R14: =IFERROR(Q14*VLOOKUP(A14,'Initiative Log'!$A:$S,19,0),0) -> 20125 | S14: =Q14 -> 100625 | T14: =IFERROR(VLOOKUP(A14,'Initiative Log'!$A:$E,5,0),"") -> G&A / HC | U14: =IFERROR(VLOOKUP(A14,'Initiative Log'!$A:$V,22,0),"") -> SGA | V14: =IFERROR(VLOOKUP(A14,'Initiative Log'!$A:$L,12,0),"") -> Pipeline | W14: =IFERROR(VLOOKUP(A14,'Initiative Log'!$A:$H,8,0),"") -> CSO | X14: =IFERROR(VLOOKUP(A14,'Initiative Log'!$A:$C,3,0),"") -> GY
... A22: I-010 | B22: Dx | C22: IT | D22: [Position Eliminated] | E22: IT Infrastructure Analyst | F22: IC | G22: 1 | H22: 92000 | I22: 9200 | J22: =H22+I22 -> 101200 | K22: =J22*0.25 -> 25300 | L22: =J22+K22 -> 126500 | M22: 12 | N22: =(H22/52)*M22 -> 21230.769 | O22: 2500 | P22: =N22+O22 -> 23730.769 | Q22: =L22 -> 126500 | R22: =IFERROR(Q22*VLOOKUP(A22,'Initiative Log'!$A:$S,19,0),0) -> 25300 | S22: =Q22 -> 126500 | T22: =IFERROR(VLOOKUP(A22,'Initiative Log'!$A:$E,5,0),"") -> G&A / HC | U22: =IFERROR(VLOOKUP(A22,'Initiative Log'!$A:$V,22,0),"") -> SGA | V22: =IFERROR(VLOOKUP(A22,'Initiative Log'!$A:$L,12,0),"") -> Pipeline | W22: =IFERROR(VLOOKUP(A22,'Initiative Log'!$A:$H,8,0),"") -> CIO | X22: =IFERROR(VLOOKUP(A22,'Initiative Log'!$A:$C,3,0),"") -> Dx
A23: TOTALS | G23: =SUM(G3:G22) -> 20 | H23: =SUM(H3:H22) -> 2484000 | I23: =SUM(I3:I22) -> 347200 | J23: =SUM(J3:J22) -> 2831200 | K23: =SUM(K3:K22) -> 707800 | L23: =SUM(L3:L22) -> 3539000 | N23: =SUM(N3:N22) -> 981115.38 | O23: =SUM(O3:O22) -> 89000 | P23: =SUM(P3:P22) -> 1070115.4 | Q23: =SUM(Q3:Q22) -> 3539000 | R23: =SUM(R3:R22) -> 1512525 | S23: =SUM(S3:S22) -> 3539000

Sheet Non-HC Detail
A1: COMPANY A | Non-HC Detail | Manual Input + Auto-Tag Columns from Initiative Log
A2: Initiative ID | B2: GL Code | C2: Segment | D2: Topic | E2: Sub-Category | F2: Initiative Name | G2: Owner | H2: Baseline Cost ($) | I2: Gross Annual Savings ($) | J2: One-Time Impl. Cost ($) | K2: Net Annual Savings ($) | L2: Yr1 Realized Savings ($) | M2: Run-Rate Annual ($) | N2: Savings % vs Baseline | O2: Payback Period (Yrs) | P2: Upside Scenario ($) | Q2: vs. Upside ($ Gap) | R2: vs. Upside (% Gap) | S2: Baseline Scenario ($) | T2: vs. Baseline ($ Gap) | U2: vs. Baseline (% Gap) | V2: P&L Line [auto] | W2: Status [auto] | X2: Yr1% [auto] | Y2: Yr2% [auto] | Z2: Yr3% [auto]
A3: I-011 | B3: 7100 | C3: Dx | D3: Manufacturing | E3: Facility | F3: San Diego Mfg Plant Closure | G3: COO | H3: 4200000 | I3: 4200000 | J3: 1800000 | K3: =I3-J3 -> 2400000 | L3: =IFERROR(I3*X3,0) -> 1260000 | M3: =I3 -> 4200000 | N3: =IFERROR(I3/H3,0) -> 1 | O3: =IFERROR(J3/I3,0) -> 0.42857143 | P3: 4830000 | Q3: =I3-P3 -> -630000 | R3: =IFERROR(I3/P3-1,0) -> -0.13043478 | S3: 3570000 | T3: =I3-S3 -> 630000 | U3: =IFERROR(I3/S3-1,0) -> 0.17647059 | V3: =IFERROR(VLOOKUP(A3,'Initiative Log'!$A:$V,22,0),"") -> COGS | W3: =IFERROR(VLOOKUP(A3,'Initiative Log'!$A:$L,12,0),"") -> Active | X3: =IFERROR(VLOOKUP(A3,'Initiative Log'!$A:$S,19,0),0) -> 0.3 | Y3: =IFERROR(VLOOKUP(A3,'Initiative Log'!$A:$T,20,0),0) -> 0.8 | Z3: =IFERROR(VLOOKUP(A3,'Initiative Log'!$A:$U,21,0),0) -> 1
